2020-07-02 19:59:50,727 (11484/MainThread) pgcli.main INFO - No default pager found in environment. Using os default pager
2020-07-02 20:01:07,703 (11502/MainThread) pgcli.main INFO - No default pager found in environment. Using os default pager
2020-07-02 20:01:07,979 (11502/MainThread) pgcli.main ERROR - traceback: 'Traceback (most recent call last):\n  File "/usr/lib/python3.8/site-packages/pgcli/main.py", line 549, in connect\n    pgexecute = PGExecute(database, user, passwd, host, port, dsn, **kwargs)\n  File "/usr/lib/python3.8/site-packages/pgcli/pgexecute.py", line 214, in __init__\n    self.connect(database, user, password, host, port, dsn, **kwargs)\n  File "/usr/lib/python3.8/site-packages/pgcli/pgexecute.py", line 254, in connect\n    conn = psycopg2.connect(**conn_params)\n  File "/usr/lib/python3.8/site-packages/psycopg2/__init__.py", line 127, in connect\n    conn = _connect(dsn, connection_factory=connection_factory, **kwasync)\n  File "/usr/lib/python3.8/site-packages/pgcli/pgexecute.py", line 39, in _wait_select\n    state = conn.poll()\npsycopg2.OperationalError\n\nDuring handling of the above exception, another exception occurred:\n\nTraceback (most recent call last):\n  File "/usr/lib/python3.8/site-packages/pgcli/main.py", line 551, in connect\n    if should_ask_for_password(e):\n  File "/usr/lib/python3.8/site-packages/pgcli/main.py", line 536, in should_ask_for_password\n    error_msg = exc.args[0]\nIndexError: tuple index out of range\n'
2020-07-02 20:04:13,158 (11509/MainThread) pgcli.main INFO - No default pager found in environment. Using os default pager
2020-07-02 20:04:13,247 (11509/MainThread) pgcli.main ERROR - traceback: 'Traceback (most recent call last):\n  File "/usr/lib/python3.8/site-packages/pgcli/main.py", line 549, in connect\n    pgexecute = PGExecute(database, user, passwd, host, port, dsn, **kwargs)\n  File "/usr/lib/python3.8/site-packages/pgcli/pgexecute.py", line 214, in __init__\n    self.connect(database, user, password, host, port, dsn, **kwargs)\n  File "/usr/lib/python3.8/site-packages/pgcli/pgexecute.py", line 254, in connect\n    conn = psycopg2.connect(**conn_params)\n  File "/usr/lib/python3.8/site-packages/psycopg2/__init__.py", line 127, in connect\n    conn = _connect(dsn, connection_factory=connection_factory, **kwasync)\n  File "/usr/lib/python3.8/site-packages/pgcli/pgexecute.py", line 39, in _wait_select\n    state = conn.poll()\npsycopg2.OperationalError\n\nDuring handling of the above exception, another exception occurred:\n\nTraceback (most recent call last):\n  File "/usr/lib/python3.8/site-packages/pgcli/main.py", line 551, in connect\n    if should_ask_for_password(e):\n  File "/usr/lib/python3.8/site-packages/pgcli/main.py", line 536, in should_ask_for_password\n    error_msg = exc.args[0]\nIndexError: tuple index out of range\n'
2020-07-02 20:10:33,361 (11523/MainThread) pgcli.main INFO - No default pager found in environment. Using os default pager
2020-07-02 20:10:39,825 (11523/MainThread) pgcli.main ERROR - traceback: 'Traceback (most recent call last):\n  File "/usr/lib/python3.8/site-packages/pgcli/main.py", line 549, in connect\n    pgexecute = PGExecute(database, user, passwd, host, port, dsn, **kwargs)\n  File "/usr/lib/python3.8/site-packages/pgcli/pgexecute.py", line 214, in __init__\n    self.connect(database, user, password, host, port, dsn, **kwargs)\n  File "/usr/lib/python3.8/site-packages/pgcli/pgexecute.py", line 254, in connect\n    conn = psycopg2.connect(**conn_params)\n  File "/usr/lib/python3.8/site-packages/psycopg2/__init__.py", line 127, in connect\n    conn = _connect(dsn, connection_factory=connection_factory, **kwasync)\n  File "/usr/lib/python3.8/site-packages/pgcli/pgexecute.py", line 39, in _wait_select\n    state = conn.poll()\npsycopg2.OperationalError\n\nDuring handling of the above exception, another exception occurred:\n\nTraceback (most recent call last):\n  File "/usr/lib/python3.8/site-packages/pgcli/main.py", line 551, in connect\n    if should_ask_for_password(e):\n  File "/usr/lib/python3.8/site-packages/pgcli/main.py", line 536, in should_ask_for_password\n    error_msg = exc.args[0]\nIndexError: tuple index out of range\n'
2020-07-02 20:10:41,712 (11532/MainThread) pgcli.main INFO - No default pager found in environment. Using os default pager
2020-07-02 20:10:44,443 (11532/MainThread) pgcli.main ERROR - traceback: 'Traceback (most recent call last):\n  File "/usr/lib/python3.8/site-packages/pgcli/main.py", line 549, in connect\n    pgexecute = PGExecute(database, user, passwd, host, port, dsn, **kwargs)\n  File "/usr/lib/python3.8/site-packages/pgcli/pgexecute.py", line 214, in __init__\n    self.connect(database, user, password, host, port, dsn, **kwargs)\n  File "/usr/lib/python3.8/site-packages/pgcli/pgexecute.py", line 254, in connect\n    conn = psycopg2.connect(**conn_params)\n  File "/usr/lib/python3.8/site-packages/psycopg2/__init__.py", line 127, in connect\n    conn = _connect(dsn, connection_factory=connection_factory, **kwasync)\n  File "/usr/lib/python3.8/site-packages/pgcli/pgexecute.py", line 39, in _wait_select\n    state = conn.poll()\npsycopg2.OperationalError\n\nDuring handling of the above exception, another exception occurred:\n\nTraceback (most recent call last):\n  File "/usr/lib/python3.8/site-packages/pgcli/main.py", line 551, in connect\n    if should_ask_for_password(e):\n  File "/usr/lib/python3.8/site-packages/pgcli/main.py", line 536, in should_ask_for_password\n    error_msg = exc.args[0]\nIndexError: tuple index out of range\n'
2020-07-02 20:11:30,198 (11539/MainThread) pgcli.main INFO - No default pager found in environment. Using os default pager
2020-07-02 20:11:35,879 (11539/MainThread) pgcli.main ERROR - traceback: 'Traceback (most recent call last):\n  File "/usr/lib/python3.8/site-packages/pgcli/main.py", line 549, in connect\n    pgexecute = PGExecute(database, user, passwd, host, port, dsn, **kwargs)\n  File "/usr/lib/python3.8/site-packages/pgcli/pgexecute.py", line 214, in __init__\n    self.connect(database, user, password, host, port, dsn, **kwargs)\n  File "/usr/lib/python3.8/site-packages/pgcli/pgexecute.py", line 254, in connect\n    conn = psycopg2.connect(**conn_params)\n  File "/usr/lib/python3.8/site-packages/psycopg2/__init__.py", line 127, in connect\n    conn = _connect(dsn, connection_factory=connection_factory, **kwasync)\n  File "/usr/lib/python3.8/site-packages/pgcli/pgexecute.py", line 39, in _wait_select\n    state = conn.poll()\npsycopg2.OperationalError\n\nDuring handling of the above exception, another exception occurred:\n\nTraceback (most recent call last):\n  File "/usr/lib/python3.8/site-packages/pgcli/main.py", line 551, in connect\n    if should_ask_for_password(e):\n  File "/usr/lib/python3.8/site-packages/pgcli/main.py", line 536, in should_ask_for_password\n    error_msg = exc.args[0]\nIndexError: tuple index out of range\n'
2020-07-02 20:12:03,425 (11548/MainThread) pgcli.main INFO - No default pager found in environment. Using os default pager
2020-07-02 20:12:06,586 (11548/MainThread) pgcli.main ERROR - traceback: 'Traceback (most recent call last):\n  File "/usr/lib/python3.8/site-packages/pgcli/main.py", line 549, in connect\n    pgexecute = PGExecute(database, user, passwd, host, port, dsn, **kwargs)\n  File "/usr/lib/python3.8/site-packages/pgcli/pgexecute.py", line 214, in __init__\n    self.connect(database, user, password, host, port, dsn, **kwargs)\n  File "/usr/lib/python3.8/site-packages/pgcli/pgexecute.py", line 254, in connect\n    conn = psycopg2.connect(**conn_params)\n  File "/usr/lib/python3.8/site-packages/psycopg2/__init__.py", line 127, in connect\n    conn = _connect(dsn, connection_factory=connection_factory, **kwasync)\n  File "/usr/lib/python3.8/site-packages/pgcli/pgexecute.py", line 39, in _wait_select\n    state = conn.poll()\npsycopg2.OperationalError\n\nDuring handling of the above exception, another exception occurred:\n\nTraceback (most recent call last):\n  File "/usr/lib/python3.8/site-packages/pgcli/main.py", line 551, in connect\n    if should_ask_for_password(e):\n  File "/usr/lib/python3.8/site-packages/pgcli/main.py", line 536, in should_ask_for_password\n    error_msg = exc.args[0]\nIndexError: tuple index out of range\n'
2020-07-02 20:12:11,866 (11555/MainThread) pgcli.main INFO - No default pager found in environment. Using os default pager
2020-07-02 20:12:49,386 (11562/MainThread) pgcli.main INFO - No default pager found in environment. Using os default pager
2020-07-02 20:13:45,279 (11621/MainThread) pgcli.main INFO - No default pager found in environment. Using os default pager
